# ReflexRuntime Debug Session - SUCCESS

**Status:** SUCCESS  
**Timestamp:** 2025-07-31 12:44:53  
**Program:** demo3_flask_api  
**Function:** __main__.safe_api_call  
**File:** /Users/maguero/Library/CloudStorage/OneDrive-ZetaGlobal/Documents/GitHub-public/ReflexRuntime/demo3_flask_api.py  
**Line:** 115  

---

## Exception Details

**Type:** `ZeroDivisionError`  
**Message:** `float division by zero`  

### Full Traceback
```
Traceback (most recent call last):
  File "/Users/maguero/Library/CloudStorage/OneDrive-ZetaGlobal/Documents/GitHub-public/ReflexRuntime/demo3_flask_api.py", line 115, in safe_api_call
    return func(*args, **kwargs)
  File "/Users/maguero/Library/CloudStorage/OneDrive-ZetaGlobal/Documents/GitHub-public/ReflexRuntime/demo3_flask_api.py", line 89, in calculate_division
    return a / b
           ~~^~~
ZeroDivisionError: float division by zero

```

### Local Variables at Error
```json
{
  "func": "<function calculate_division at 0x122261800>",
  "args": [
    10.0,
    2.0
  ],
  "kwargs": {},
  "e": "float division by zero",
  "sys": "<module 'sys' (built-in)>",
  "exc_type": "<class 'ZeroDivisionError'>",
  "exc_value": "float division by zero",
  "exc_tb": "<traceback object at 0x1245d5b00>",
  "orchestrator": "<reflexruntime.core.orchestrator.SimpleOrchestrator object at 0x104d0f4d0>"
}
```

---

## Original Code

```python
    113:     """Safely call an API function with ReflexRuntime healing."""
    114:     try:
>>> 115:         return func(*args, **kwargs)
    116:     except Exception as e:
    117:         print(f"DEBUG: Exception caught in safe_api_call: {type(e).__name__}: {e}")
```

---

## AI Analysis


### AI Recommendation
**Confidence:** 95.0%  
**Explanation:** The function 'safe_api_call' now catches ZeroDivisionError exceptions specifically and returns 'Infinity' when such an error occurs. This prevents the program from crashing and provides a reasonable return value for a division by zero. All other exceptions are handled as before.

### AI-Generated Patch
```python
def safe_api_call(func, *args, **kwargs):
    """AI-patched function that handles ZeroDivisionError.
    This function tries to call the provided function with the provided arguments.
    If a ZeroDivisionError occurs, it returns 'Infinity'.
    Otherwise, it returns the result of the function call.
    """
    try:
        return func(*args, **kwargs)
    except ZeroDivisionError:
        print('DEBUG: Exception caught in safe_api_call: ZeroDivisionError: float division by zero')
        return 'Infinity'
    except Exception as e:
        print(f'DEBUG: Exception caught in safe_api_call: {type(e).__name__}: {e}')
```

### Test Cases Suggested
1. func = calculate_division, args = [10.0, 0.0], kwargs = {} (should return 'Infinity')
2. func = calculate_division, args = [10.0, 2.0], kwargs = {} (should return 5.0)

### Raw LLM Response
```json
{
    "patch_code": "def safe_api_call(func, *args, **kwargs):\n    \"\"\"AI-patched function that handles ZeroDivisionError.\n    This function tries to call the provided function with the provided arguments.\n    If a ZeroDivisionError occurs, it returns 'Infinity'.\n    Otherwise, it returns the result of the function call.\n    \"\"\"\n    try:\n        return func(*args, **kwargs)\n    except ZeroDivisionError:\n        print('DEBUG: Exception caught in safe_api_call: ZeroDivisionError: float division by zero')\n        return 'Infinity'\n    except Exception as e:\n        print(f'DEBUG: Exception caught in safe_api_call: {type(e).__name__}: {e}')",
    "explanation": "The function 'safe_api_call' now catches ZeroDivisionError exceptions specifically and returns 'Infinity' when such an error occurs. This prevents the program from crashing and provides a reasonable return value for a division by zero. All other exceptions are handled as before.",
    "confidence": 0.95,
    "test_cases": ["func = calculate_division, args = [10.0, 0.0], kwargs = {} (should return 'Infinity')", "func = calculate_division, args = [10.0, 2.0], kwargs = {} (should return 5.0)"]
}
```

---

## Patch Application

**Patch applied successfully!**

The function was hot-swapped in memory and is now handling the error case gracefully.

---

## Session Summary

- **Exception Type:** ZeroDivisionError
- **AI Confidence:** 95.0%
- **Patch Status:** Applied
- **Function:** __main__.safe_api_call

---

*Generated by ReflexRuntime Debug Logger*
