# ReflexRuntime Debug Session - SUCCESS

**Status:** SUCCESS  
**Timestamp:** 2025-07-31 12:37:56  
**Program:** demo1_division_calculator  
**Function:** __main__.main  
**File:** /Users/maguero/Library/CloudStorage/OneDrive-ZetaGlobal/Documents/GitHub-public/ReflexRuntime/demo1_division_calculator.py  
**Line:** 54  

---

## Exception Details

**Type:** `ZeroDivisionError`  
**Message:** `float division by zero`  

### Full Traceback
```
Traceback (most recent call last):
  File "/Users/maguero/Library/CloudStorage/OneDrive-ZetaGlobal/Documents/GitHub-public/ReflexRuntime/demo1_division_calculator.py", line 54, in main
    result = divide_numbers(a, b)
  File "/Users/maguero/Library/CloudStorage/OneDrive-ZetaGlobal/Documents/GitHub-public/ReflexRuntime/demo1_division_calculator.py", line 21, in divide_numbers
    return a / b
           ~~^~~
ZeroDivisionError: float division by zero

```

### Local Variables at Error
```json
{
  "calculation_count": 2,
  "a": 5.0,
  "b": 0.0,
  "result": 3.0,
  "e": "float division by zero",
  "sys": "<module 'sys' (built-in)>",
  "get_simple_orchestrator": "<function get_simple_orchestrator at 0x106b95c60>",
  "exc_type": "<class 'ZeroDivisionError'>",
  "exc_value": "float division by zero",
  "exc_tb": "<traceback object at 0x1005fec40>",
  "orchestrator": "<reflexruntime.core.orchestrator.SimpleOrchestrator object at 0x1009a2e40>"
}
```

---

## Original Code

```python
    52:         # Let division errors bubble up to ReflexRuntime
    53:         try:
>>> 54:             result = divide_numbers(a, b)
    55:             print(f"Result: {a} รท {b} = {result}")
    56: 
```

---

## AI Analysis


### AI Recommendation
**Confidence:** 95.0%  
**Explanation:** The function now catches ZeroDivisionError exceptions and instead of crashing, it prints an error message and returns None. For valid inputs, the function operates as before.

### AI-Generated Patch
```python
def main(a, b):
    """AI-patched function that handles ZeroDivisionError."""
    try:
        result = divide_numbers(a, b)
    except ZeroDivisionError:
        print('Error: Division by zero is not allowed.')
        result = None
    else:
        print(f'Result: {a} รท {b} = {result}')
    return result
```

### Test Cases Suggested
1. main(5.0, 0.0) should trigger the original error and now returns None
2. main(5.0, 2.0) should work normally and return 2.5

### Raw LLM Response
```json
{
    "patch_code": "def main(a, b):\n    \"\"\"AI-patched function that handles ZeroDivisionError.\"\"\"\n    try:\n        result = divide_numbers(a, b)\n    except ZeroDivisionError:\n        print('Error: Division by zero is not allowed.')\n        result = None\n    else:\n        print(f'Result: {a} รท {b} = {result}')\n    return result",
    "explanation": "The function now catches ZeroDivisionError exceptions and instead of crashing, it prints an error message and returns None. For valid inputs, the function operates as before.",
    "confidence": 0.95,
    "test_cases": ["main(5.0, 0.0) should trigger the original error and now returns None", "main(5.0, 2.0) should work normally and return 2.5"]
}
```

---

## Patch Application

**Patch applied successfully!**

The function was hot-swapped in memory and is now handling the error case gracefully.

---

## Session Summary

- **Exception Type:** ZeroDivisionError
- **AI Confidence:** 95.0%
- **Patch Status:** Applied
- **Function:** __main__.main

---

*Generated by ReflexRuntime Debug Logger*
